{"uuid": "a7001126-8a6e-4b73-84bd-b34f5ca62a4f", "counter": 97, "stdout": "\u001b[0;31mfatal: [localhost]: FAILED! => {\"changed\": false, \"module_stderr\": \"ModuleNotFoundError: No module named '_cffi_backend'\\nthread '<unnamed>' panicked at /github/home/.cargo/registry/src/index.crates.io-6f17d22bba15001f/pyo3-0.20.3/src/err/mod.rs:788:5:\\nPython API call failed\\nnote: run with `RUST_BACKTRACE=1` environment variable to display a backtrace\\nTraceback (most recent call last):\\n  File \\\"/home/codespace/.ansible/tmp/ansible-tmp-1710364822.5733619-53075-69479930582367/AnsiballZ_apt.py\\\", line 107, in <module>\\n    _ansiballz_main()\\n  File \\\"/home/codespace/.ansible/tmp/ansible-tmp-1710364822.5733619-53075-69479930582367/AnsiballZ_apt.py\\\", line 99, in _ansiballz_main\\n    invoke_module(zipped_mod, temp_path, ANSIBALLZ_PARAMS)\\n  File \\\"/home/codespace/.ansible/tmp/ansible-tmp-1710364822.5733619-53075-69479930582367/AnsiballZ_apt.py\\\", line 47, in invoke_module\\n    runpy.run_module(mod_name='ansible.modules.apt', init_globals=dict(_module_fqn='ansible.modules.apt', _modlib_path=modlib_path),\\n  File \\\"/usr/local/python/3.10.13/lib/python3.10/runpy.py\\\", line 224, in run_module\\n    return _run_module_code(code, init_globals, run_name, mod_spec)\\n  File \\\"/usr/local/python/3.10.13/lib/python3.10/runpy.py\\\", line 96, in _run_module_code\\n    _run_code(code, mod_globals, init_globals,\\n  File \\\"/usr/local/python/3.10.13/lib/python3.10/runpy.py\\\", line 86, in _run_code\\n    exec(code, run_globals)\\n  File \\\"/tmp/ansible_apt_payload_y7yeszp7/ansible_apt_payload.zip/ansible/modules/apt.py\\\", line 377, in <module>\\n  File \\\"/tmp/ansible_apt_payload_y7yeszp7/ansible_apt_payload.zip/ansible/module_utils/urls.py\\\", line 190, in <module>\\n  File \\\"/usr/local/python/3.10.13/lib/python3.10/site-packages/cryptography/x509/__init__.py\\\", line 7, in <module>\\n    from cryptography.x509 import certificate_transparency, verification\\n  File \\\"/usr/local/python/3.10.13/lib/python3.10/site-packages/cryptography/x509/certificate_transparency.py\\\", line 11, in <module>\\n    from cryptography.hazmat.bindings._rust import x509 as rust_x509\\npyo3_runtime.PanicException: Python API call failed\\n\", \"module_stdout\": \"\", \"msg\": \"MODULE FAILURE\\nSee stdout/stderr for the exact error\", \"rc\": 1}\u001b[0m", "start_line": 71, "end_line": 72, "runner_ident": "225b6352-0b5f-43fe-ac8d-129b5b08e9bd", "event": "runner_on_failed", "pid": 50591, "created": "2024-03-13T21:20:23.014747", "parent_uuid": "002248ba-75d0-89fe-840c-000000000014", "event_data": {"playbook": "/workspaces/ensf400-lab5-ansible/hello.yml", "playbook_uuid": "db97c373-e5d9-4704-851d-b053e252ec15", "play": "Play - Install and configure Nginx as a LoadBalancer", "play_uuid": "002248ba-75d0-89fe-840c-000000000012", "play_pattern": "localhost", "task": "Update cache", "task_uuid": "002248ba-75d0-89fe-840c-000000000014", "task_action": "apt", "resolved_action": "ansible.builtin.apt", "task_args": "", "task_path": "/workspaces/ensf400-lab5-ansible/hello.yml:92", "host": "localhost", "remote_addr": "127.0.0.1", "res": {"module_stdout": "", "module_stderr": "ModuleNotFoundError: No module named '_cffi_backend'\nthread '<unnamed>' panicked at /github/home/.cargo/registry/src/index.crates.io-6f17d22bba15001f/pyo3-0.20.3/src/err/mod.rs:788:5:\nPython API call failed\nnote: run with `RUST_BACKTRACE=1` environment variable to display a backtrace\nTraceback (most recent call last):\n  File \"/home/codespace/.ansible/tmp/ansible-tmp-1710364822.5733619-53075-69479930582367/AnsiballZ_apt.py\", line 107, in <module>\n    _ansiballz_main()\n  File \"/home/codespace/.ansible/tmp/ansible-tmp-1710364822.5733619-53075-69479930582367/AnsiballZ_apt.py\", line 99, in _ansiballz_main\n    invoke_module(zipped_mod, temp_path, ANSIBALLZ_PARAMS)\n  File \"/home/codespace/.ansible/tmp/ansible-tmp-1710364822.5733619-53075-69479930582367/AnsiballZ_apt.py\", line 47, in invoke_module\n    runpy.run_module(mod_name='ansible.modules.apt', init_globals=dict(_module_fqn='ansible.modules.apt', _modlib_path=modlib_path),\n  File \"/usr/local/python/3.10.13/lib/python3.10/runpy.py\", line 224, in run_module\n    return _run_module_code(code, init_globals, run_name, mod_spec)\n  File \"/usr/local/python/3.10.13/lib/python3.10/runpy.py\", line 96, in _run_module_code\n    _run_code(code, mod_globals, init_globals,\n  File \"/usr/local/python/3.10.13/lib/python3.10/runpy.py\", line 86, in _run_code\n    exec(code, run_globals)\n  File \"/tmp/ansible_apt_payload_y7yeszp7/ansible_apt_payload.zip/ansible/modules/apt.py\", line 377, in <module>\n  File \"/tmp/ansible_apt_payload_y7yeszp7/ansible_apt_payload.zip/ansible/module_utils/urls.py\", line 190, in <module>\n  File \"/usr/local/python/3.10.13/lib/python3.10/site-packages/cryptography/x509/__init__.py\", line 7, in <module>\n    from cryptography.x509 import certificate_transparency, verification\n  File \"/usr/local/python/3.10.13/lib/python3.10/site-packages/cryptography/x509/certificate_transparency.py\", line 11, in <module>\n    from cryptography.hazmat.bindings._rust import x509 as rust_x509\npyo3_runtime.PanicException: Python API call failed\n", "msg": "MODULE FAILURE\nSee stdout/stderr for the exact error", "rc": 1, "_ansible_no_log": false, "changed": false}, "start": "2024-03-13T21:20:22.547274", "end": "2024-03-13T21:20:23.014512", "duration": 0.467238, "ignore_errors": null, "event_loop": null, "uuid": "a7001126-8a6e-4b73-84bd-b34f5ca62a4f"}}